Workbook

Sheet README
B2: Review Engine
B3: ShelfMark's 29 checks as a standing rubric for any store · index of 21 benchmark stores + 3 reviewed targets · 2026-09-28 · Mousa Batarseh
B5: What this is | C5: The spreadsheet behind every store review I send with an application. One rubric (29 public-page checks, 5 pillars, 0–100 score) scores any storefront in about an hour; the ShelfMark index of 21 Michigan stores is the comparison pool, so each target gets a rank, not just a number; and every role-specific finding is filed in a library that the next review reuses.
B6: How a score is built | C6: Each check is 2 (meets), 1 (partly), 0 (fails) or U (unverified from public pages). Pillar % = verified points ÷ (2 × verified checks). Score = weighted average of pillar % (weights on Rubric: Findability 25, Catalog 30, Buy 20, Trust 15, Content 10). U never counts for or against a store; Coverage and Confidence show how much was observable. Identical to the ShelfMark workbook, so scores are comparable.
B7: Sheets | C7: Rubric — pillars, weights, thresholds, the 29 checks and the published reference behind each one. Index — every store scored, benchmark and targets together (targets shaded blue), with live formulas. Checks — 29 observations per store with dated evidence; the only place scores are typed. Findings — the library: strengths, fixes and role-specific findings with counts, the duty they map to, the fix and the evidence file. Impact ledger — my own outcomes with source and confidence, the single source of truth for résumé bullets. Outreach — one row per person contacted, with status and follow-up dates. Messages — the notes that go with a review.
B8: The one-hour review | C8: 1) Paste the target's homepage, robots.txt, sitemap, one category and two product URLs into the audit brief (audit-brief.md). 2) Score the 29 checks with evidence into targets/<slug>/audit.json. 3) Read the posting; find 4–6 findings that can be COUNTED across sampled pages and map each to a duty in the posting. 4) python3 build_workbook.py && python3 build_review.py <slug> — the scorecard, rank, workbook and review page are generated. 5) Write the working fixes (prototypes) by hand in the company's look. 6) Send: application link + one finding to one named person within 48 hours; log the row on Outreach.
B9: Rules | C9: Public pages only; never log in, cart or submit forms. Count things (14 of 20), never characterize ("many"). Lead with three strengths. Every finding names the page, the count, the duty it maps to and the fix. No claims about health, legal or financial language. Review pages are noindex and sent as private links to one person.
B10: Legend | C10: Blue text on yellow = typed inputs (scores, contacts, statuses). Black = formulas. Green = pulled from another sheet. Blue-shaded rows on Index = reviewed targets (not part of the public benchmark).
B11: Author | C11: Mousa Batarseh · hireme@mousabatarseh.com · mousabatarseh.com · linkedin.com/in/mousabatarseh

Sheet Index
A1: Rank (all) | B1: Rank on the benchmark | C1: Store | D1: Source | E1: Segment | F1: Platform | G1: HQ | H1: URL | I1: Audited | J1: Findability % | K1: F n | L1: Catalog % | M1: C n | N1: Buy % | O1: B n | P1: Trust % | Q1: T n | R1: Content % | S1: N n | T1: Verified (of 29) | U1: Coverage | V1: Confidence | W1: Score | X1: Grade | Y1: Band | Z1: Weakest pillar | AA1: Review page | AB1: Notes
A2: =IF(W2="","",RANK(W2,$W$2:$W$25,0)) -> 2 | B2: =IF(W2="","",1+COUNTIFS($D$2:$D$25,"Benchmark",$W$2:$W$25,">"&W2)) -> 1 | C2: Stormy Kromer | D2: Benchmark | E2: Brand & maker | F2: BigCommerce | G2: Ironwood, MI | H2: https://www.stormykromer.com | I2: 2026-09-28 | J2: =IFERROR(SUMIFS(Checks!$F$2:$F$1297,Checks!$A$2:$A$1297,$C2,Checks!$C$2:$C$1297,"F")/(2*COUNTIFS(Checks!$A$2:$A$1297,$C2,Checks!$C$2:$C$1297,"F",Checks!$F$2:$F$1297,">=0")),"") -> 0.9375 | K2: =COUNTIFS(Checks!$A$2:$A$1297,$C2,Checks!$C$2:$C$1297,"F",Checks!$F$2:$F$1297,">=0") -> 8 | L2: =IFERROR(SUMIFS(Checks!$F$2:$F$1297,Checks!$A$2:$A$1297,$C2,Checks!$C$2:$C$1297,"C")/(2*COUNTIFS(Checks!$A$2:$A$1297,$C2,Checks!$C$2:$C$1297,"C",Checks!$F$2:$F$1297,">=0")),"") -> 1 | M2: =COUNTIFS(Checks!$A$2:$A$1297,$C2,Checks!$C$2:$C$1297,"C",Checks!$F$2:$F$1297,">=0") -> 8 | N2: =IFERROR(SUMIFS(Checks!$F$2:$F$1297,Checks!$A$2:$A$1297,$C2,Checks!$C$2:$C$1297,"B")/(2*COUNTIFS(Checks!$A$2:$A$1297,$C2,Checks!$C$2:$C$1297,"B",Checks!$F$2:$F$1297,">=0")),"") -> 1 | O2: =COUNTIFS(Checks!$A$2:$A$1297,$C2,Checks!$C$2:$C$1297,"B",Checks!$F$2:$F$1297,">=0") -> 4 | P2: =IFERROR(SUMIFS(Checks!$F$2:$F$1297,Checks!$A$2:$A$1297,$C2,Checks!$C$2:$C$1297,"T")/(2*COUNTIFS(Checks!$A$2:$A$1297,$C2,Checks!$C$2:$C$1297,"T",Checks!$F$2:$F$1297,">=0")),"") -> 1 | Q2: =COUNTIFS(Checks!$A$2:$A$1297,$C2,Checks!$C$2:$C$1297,"T",Checks!$F$2:$F$1297,">=0") -> 5 | R2: =IFERROR(SUMIFS(Checks!$F$2:$F$1297,Checks!$A$2:$A$1297,$C2,Checks!$C$2:$C$1297,"N")/(2*COUNTIFS(Checks!$A$2:$A$1297,$C2,Checks!$C$2:$C$1297,"N",Checks!$F$2:$F$1297,">=0")),"") -> 0.66666667 | S2: =COUNTIFS(Checks!$A$2:$A$1297,$C2,Checks!$C$2:$C$1297,"N",Checks!$F$2:$F$1297,">=0") -> 3 | T2: =K2+M2+O2+Q2+S2 -> 28 | U2: =T2/29 -> 0.96551724 | V2: =IF(T2>=26,"High",IF(T2>=20,"Medium","Low")) -> High | W2: =IF((IF(K2>0,Rubric!$C$3,0)+IF(M2>0,Rubric!$C$4,0)+IF(O2>0,Rubric!$C$5,0)+IF(Q2>0,Rubric!$C$6,0)+IF(S2>0,Rubric!$C$7,0))=0,"",ROUND(100*(IF(K2>0,Rubric!$C$3*J2,0)+IF(M2>0,Rubric!$C$4*L2,0)+IF(O2>0,Rubric!$C$5*N2,0)+IF(Q2>0,Rubric!$C$6*P2,0)+IF(S2>0,Rubric!$C$7*R2,0))/(IF(K2>0,Rubric!$C$3,0)+IF(M2>0,Rubric!$C$4,0)+IF(O2>0,Rubric!$C$5,0)+IF(Q2>0,Rubric!$C$6,0)+IF(S2>0,Rubric!$C$7,0)),1)) -> 95.1 | X2: =IF(W2="","",IF(W2>=Rubric!$C$11,"A",IF(W2>=Rubric!$C$12,"B",IF(W2>=Rubric!$C$13,"C",IF(W2>=Rubric!$C$14,"D","F"))))) -> A | Y2: =IF(X2="","",IF(X2="A","Benchmark",IF(X2="B","Strong",IF(X2="C","Developing",IF(X2="D","Needs work","At risk"))))) -> Benchmark | Z2: =IF(COUNT(J2,L2,N2,P2,R2)=0,"",INDEX({"Findability","Catalog","Buy","Trust","Content"},MATCH(MIN(J2,L2,N2,P2,R2),CHOOSE({1,2,3,4,5},J2,L2,N2,P2,R2),0))) -> Content | AB2: Footer X/Twitter link points to twitter.com/i/flow/login?redirect_after_login=%2FStormyKromer rather than the profile URL. Category facet lists are collapsed in fetched HTML ('No filters applied'); facets confirmed on the search results page. robots.txt blocks GPTBot entirely while allowing OAI-SearchBot.
A3: =IF(W3="","",RANK(W3,$W$2:$W$25,0)) -> 3 | B3: =IF(W3="","",1+COUNTIFS($D$2:$D$25,"Benchmark",$W$2:$W$25,">"&W3)) -> 2 | C3: Gardner-White Furniture | D3: Benchmark | E3: Retail chain | F3: Custom | G3: Auburn Hills, MI | H3: https://www.gardner-white.com | I3: 2026-09-28 | J3: =IFERROR(SUMIFS(Checks!$F$2:$F$1297,Checks!$A$2:$A$1297,$C3,Checks!$C$2:$C$1297,"F")/(2*COUNTIFS(Checks!$A$2:$A$1297,$C3,Checks!$C$2:$C$1297,"F",Checks!$F$2:$F$1297,">=0")),"") -> 0.92857143 | K3: =COUNTIFS(Checks!$A$2:$A$1297,$C3,Checks!$C$2:$C$1297,"F",Checks!$F$2:$F$1297,">=0") -> 7 | L3: =IFERROR(SUMIFS(Checks!$F$2:$F$1297,Checks!$A$2:$A$1297,$C3,Checks!$C$2:$C$1297,"C")/(2*COUNTIFS(Checks!$A$2:$A$1297,$C3,Checks!$C$2:$C$1297,"C",Checks!$F$2:$F$1297,">=0")),"") -> 0.91666667 | M3: =COUNTIFS(Checks!$A$2:$A$1297,$C3,Checks!$C$2:$C$1297,"C",Checks!$F$2:$F$1297,">=0") -> 6 | N3: =IFERROR(SUMIFS(Checks!$F$2:$F$1297,Checks!$A$2:$A$1297,$C3,Checks!$C$2:$C$1297,"B")/(2*COUNTIFS(Checks!$A$2:$A$1297,$C3,Checks!$C$2:$C$1297,"B",Checks!$F$2:$F$1297,">=0")),"") -> 1 | O3: =COUNTIFS(Checks!$A$2:$A$1297,$C3,Checks!$C$2:$C$1297,"B",Checks!$F$2:$F$1297,">=0") -> 3 | P3: =IFERROR(SUMIFS(Checks!$F$2:$F$1297,Checks!$A$2:$A$1297,$C3,Checks!$C$2:$C$1297,"T")/(2*COUNTIFS(Checks!$A$2:$A$1297,$C3,Checks!$C$2:$C$1297,"T",Checks!$F$2:$F$1297,">=0")),"") -> 0.875 | Q3: =COUNTIFS(Checks!$A$2:$A$1297,$C3,Checks!$C$2:$C$1297,"T",Checks!$F$2:$F$1297,">=0") -> 4 | R3: =IFERROR(SUMIFS(Checks!$F$2:$F$1297,Checks!$A$2:$A$1297,$C3,Checks!$C$2:$C$1297,"N")/(2*COUNTIFS(Checks!$A$2:$A$1297,$C3,Checks!$C$2:$C$1297,"N",Checks!$F$2:$F$1297,">=0")),"") -> 1 | S3: =COUNTIFS(Checks!$A$2:$A$1297,$C3,Checks!$C$2:$C$1297,"N",Checks!$F$2:$F$1297,">=0") -> 3 | T3: =K3+M3+O3+Q3+S3 -> 23 | U3: =T3/29 -> 0.79310345 | V3: =IF(T3>=26,"High",IF(T3>=20,"Medium","Low")) -> Medium | W3: =IF((IF(K3>0,Rubric!$C$3,0)+IF(M3>0,Rubric!$C$4,0)+IF(O3>0,Rubric!$C$5,0)+IF(Q3>0,Rubric!$C$6,0)+IF(S3>0,Rubric!$C$7,0))=0,"",ROUND(100*(IF(K3>0,Rubric!$C$3*J3,0)+IF(M3>0,Rubric!$C$4*L3,0)+IF(O3>0,Rubric!$C$5*N3,0)+IF(Q3>0,Rubric!$C$6*P3,0)+IF(S3>0,Rubric!$C$7*R3,0))/(IF(K3>0,Rubric!$C$3,0)+IF(M3>0,Rubric!$C$4,0)+IF(O3>0,Rubric!$C$5,0)+IF(Q3>0,Rubric!$C$6,0)+IF(S3>0,Rubric!$C$7,0)),1)) -> 93.8 | X3: =IF(W3="","",IF(W3>=Rubric!$C$11,"A",IF(W3>=Rubric!$C$12,"B",IF(W3>=Rubric!$C$13,"C",IF(W3>=Rubric!$C$14,"D","F"))))) -> A | Y3: =IF(X3="","",IF(X3="A","Benchmark",IF(X3="B","Strong",IF(X3="C","Developing",IF(X3="D","Needs work","At risk"))))) -> Benchmark | Z3: =IF(COUNT(J3,L3,N3,P3,R3)=0,"",INDEX({"Findability","Catalog","Buy","Trust","Content"},MATCH(MIN(J3,L3,N3,P3,R3),CHOOSE({1,2,3,4,5},J3,L3,N3,P3,R3),0))) -> Trust | AB3: Custom platform behind CloudFront; PDP content only visible via rendered fetch. HQ per /terms (4445 N Atlantic Blvd, Auburn Hills); privacy policy lists the Warren address.
A4: =IF(W4="","",RANK(W4,$W$2:$W$25,0)) -> 4 | B4: =IF(W4="","",1+COUNTIFS($D$2:$D$25,"Benchmark",$W$2:$W$25,">"&W4)) -> 3 | C4: Cherry Republic | D4: Benchmark | E4: Food & drink maker | F4: Shopify | G4: Glen Arbor, MI | H4: https://www.cherryrepublic.com | I4: 2026-09-28 | J4: =IFERROR(SUMIFS(Checks!$F$2:$F$1297,Checks!$A$2:$A$1297,$C4,Checks!$C$2:$C$1297,"F")/(2*COUNTIFS(Checks!$A$2:$A$1297,$C4,Checks!$C$2:$C$1297,"F",Checks!$F$2:$F$1297,">=0")),"") -> 1 | K4: =COUNTIFS(Checks!$A$2:$A$1297,$C4,Checks!$C$2:$C$1297,"F",Checks!$F$2:$F$1297,">=0") -> 7 | L4: =IFERROR(SUMIFS(Checks!$F$2:$F$1297,Checks!$A$2:$A$1297,$C4,Checks!$C$2:$C$1297,"C")/(2*COUNTIFS(Checks!$A$2:$A$1297,$C4,Checks!$C$2:$C$1297,"C",Checks!$F$2:$F$1297,">=0")),"") -> 0.75 | M4: =COUNTIFS(Checks!$A$2:$A$1297,$C4,Checks!$C$2:$C$1297,"C",Checks!$F$2:$F$1297,">=0") -> 8 | N4: =IFERROR(SUMIFS(Checks!$F$2:$F$1297,Checks!$A$2:$A$1297,$C4,Checks!$C$2:$C$1297,"B")/(2*COUNTIFS(Checks!$A$2:$A$1297,$C4,Checks!$C$2:$C$1297,"B",Checks!$F$2:$F$1297,">=0")),"") -> 1 | O4: =COUNTIFS(Checks!$A$2:$A$1297,$C4,Checks!$C$2:$C$1297,"B",Checks!$F$2:$F$1297,">=0") -> 4 | P4: =IFERROR(SUMIFS(Checks!$F$2:$F$1297,Checks!$A$2:$A$1297,$C4,Checks!$C$2:$C$1297,"T")/(2*COUNTIFS(Checks!$A$2:$A$1297,$C4,Checks!$C$2:$C$1297,"T",Checks!$F$2:$F$1297,">=0")),"") -> 1 | Q4: =COUNTIFS(Checks!$A$2:$A$1297,$C4,Checks!$C$2:$C$1297,"T",Checks!$F$2:$F$1297,">=0") -> 5 | R4: =IFERROR(SUMIFS(Checks!$F$2:$F$1297,Checks!$A$2:$A$1297,$C4,Checks!$C$2:$C$1297,"N")/(2*COUNTIFS(Checks!$A$2:$A$1297,$C4,Checks!$C$2:$C$1297,"N",Checks!$F$2:$F$1297,">=0")),"") -> 0.83333333 | S4: =COUNTIFS(Checks!$A$2:$A$1297,$C4,Checks!$C$2:$C$1297,"N",Checks!$F$2:$F$1297,">=0") -> 3 | T4: =K4+M4+O4+Q4+S4 -> 27 | U4: =T4/29 -> 0.93103448 | V4: =IF(T4>=26,"High",IF(T4>=20,"Medium","Low")) -> High | W4: =IF((IF(K4>0,Rubric!$C$3,0)+IF(M4>0,Rubric!$C$4,0)+IF(O4>0,Rubric!$C$5,0)+IF(Q4>0,Rubric!$C$6,0)+IF(S4>0,Rubric!$C$7,0))=0,"",ROUND(100*(IF(K4>0,Rubric!$C$3*J4,0)+IF(M4>0,Rubric!$C$4*L4,0)+IF(O4>0,Rubric!$C$5*N4,0)+IF(Q4>0,Rubric!$C$6*P4,0)+IF(S4>0,Rubric!$C$7*R4,0))/(IF(K4>0,Rubric!$C$3,0)+IF(M4>0,Rubric!$C$4,0)+IF(O4>0,Rubric!$C$5,0)+IF(Q4>0,Rubric!$C$6,0)+IF(S4>0,Rubric!$C$7,0)),1)) -> 90.8 | X4: =IF(W4="","",IF(W4>=Rubric!$C$11,"A",IF(W4>=Rubric!$C$12,"B",IF(W4>=Rubric!$C$13,"C",IF(W4>=Rubric!$C$14,"D","F"))))) -> A | Y4: =IF(X4="","",IF(X4="A","Benchmark",IF(X4="B","Strong",IF(X4="C","Developing",IF(X4="D","Needs work","At risk"))))) -> Benchmark | Z4: =IF(COUNT(J4,L4,N4,P4,R4)=0,"",INDEX({"Findability","Catalog","Buy","Trust","Content"},MATCH(MIN(J4,L4,N4,P4,R4),CHOOSE({1,2,3,4,5},J4,L4,N4,P4,R4),0))) -> Catalog | AB4: Shopify. Also: add store hours to the Locations page, stock state to PDPs; blog listing hides dates (only visible on the post page).
A5: =IF(W5="","",RANK(W5,$W$2:$W$25,0)) -> 5 | B5: =IF(W5="","",1+COUNTIFS($D$2:$D$25,"Benchmark",$W$2:$W$25,">"&W5)) -> 4 | C5: American Spoon | D5: Benchmark | E5: Food & drink maker | F5: Shopify | G5: Petoskey, MI | H5: https://www.spoon.com | I5: 2026-09-28 | J5: =IFERROR(SUMIFS(Checks!$F$2:$F$1297,Checks!$A$2:$A$1297,$C5,Checks!$C$2:$C$1297,"F")/(2*COUNTIFS(Checks!$A$2:$A$1297,$C5,Checks!$C$2:$C$1297,"F",Checks!$F$2:$F$1297,">=0")),"") -> 0.9 | K5: =COUNTIFS(Checks!$A$2:$A$1297,$C5,Checks!$C$2:$C$1297,"F",Checks!$F$2:$F$1297,">=0") -> 5 | L5: =IFERROR(SUMIFS(Checks!$F$2:$F$1297,Checks!$A$2:$A$1297,$C5,Checks!$C$2:$C$1297,"C")/(2*COUNTIFS(Checks!$A$2:$A$1297,$C5,Checks!$C$2:$C$1297,"C",Checks!$F$2:$F$1297,">=0")),"") -> 0.875 | M5: =COUNTIFS(Checks!$A$2:$A$1297,$C5,Checks!$C$2:$C$1297,"C",Checks!$F$2:$F$1297,">=0") -> 8 | N5: =IFERROR(SUMIFS(Checks!$F$2:$F$1297,Checks!$A$2:$A$1297,$C5,Checks!$C$2:$C$1297,"B")/(2*COUNTIFS(Checks!$A$2:$A$1297,$C5,Checks!$C$2:$C$1297,"B",Checks!$F$2:$F$1297,">=0")),"") -> 0.875 | O5: =COUNTIFS(Checks!$A$2:$A$1297,$C5,Checks!$C$2:$C$1297,"B",Checks!$F$2:$F$1297,">=0") -> 4 | P5: =IFERROR(SUMIFS(Checks!$F$2:$F$1297,Checks!$A$2:$A$1297,$C5,Checks!$C$2:$C$1297,"T")/(2*COUNTIFS(Checks!$A$2:$A$1297,$C5,Checks!$C$2:$C$1297,"T",Checks!$F$2:$F$1297,">=0")),"") -> 1 | Q5: =COUNTIFS(Checks!$A$2:$A$1297,$C5,Checks!$C$2:$C$1297,"T",Checks!$F$2:$F$1297,">=0") -> 5 | R5: =IFERROR(SUMIFS(Checks!$F$2:$F$1297,Checks!$A$2:$A$1297,$C5,Checks!$C$2:$C$1297,"N")/(2*COUNTIFS(Checks!$A$2:$A$1297,$C5,Checks!$C$2:$C$1297,"N",Checks!$F$2:$F$1297,">=0")),"") -> 0.83333333 | S5: =COUNTIFS(Checks!$A$2:$A$1297,$C5,Checks!$C$2:$C$1297,"N",Checks!$F$2:$F$1297,">=0") -> 3 | T5: =K5+M5+O5+Q5+S5 -> 25 | U5: =T5/29 -> 0.86206897 | V5: =IF(T5>=26,"High",IF(T5>=20,"Medium","Low")) -> Medium | W5: =IF((IF(K5>0,Rubric!$C$3,0)+IF(M5>0,Rubric!$C$4,0)+IF(O5>0,Rubric!$C$5,0)+IF(Q5>0,Rubric!$C$6,0)+IF(S5>0,Rubric!$C$7,0))=0,"",ROUND(100*(IF(K5>0,Rubric!$C$3*J5,0)+IF(M5>0,Rubric!$C$4*L5,0)+IF(O5>0,Rubric!$C$5*N5,0)+IF(Q5>0,Rubric!$C$6*P5,0)+IF(S5>0,Rubric!$C$7*R5,0))/(IF(K5>0,Rubric!$C$3,0)+IF(M5>0,Rubric!$C$4,0)+IF(O5>0,Rubric!$C$5,0)+IF(Q5>0,Rubric!$C$6,0)+IF(S5>0,Rubric!$C$7,0)),1)) -> 89.6 | X5: =IF(W5="","",IF(W5>=Rubric!$C$11,"A",IF(W5>=Rubric!$C$12,"B",IF(W5>=Rubric!$C$13,"C",IF(W5>=Rubric!$C$14,"D","F"))))) -> A | Y5: =IF(X5="","",IF(X5="A","Benchmark",IF(X5="B","Strong",IF(X5="C","Developing",IF(X5="D","Needs work","At risk"))))) -> Benchmark | Z5: =IF(COUNT(J5,L5,N5,P5,R5)=0,"",INDEX({"Findability","Catalog","Buy","Trust","Content"},MATCH(MIN(J5,L5,N5,P5,R5),CHOOSE({1,2,3,4,5},J5,L5,N5,P5,R5),0))) -> Content | AB5: Shopify. WebFetch surfaced no <head> meta block for spoon.com, so meta description and canonical are U. Collection handles carry a 'website-' prefix; /blogs/recipes 404s (recipes live under /pages/).
A6: =IF(W6="","",RANK(W6,$W$2:$W$25,0)) -> 6 | B6: =IF(W6="","",1+COUNTIFS($D$2:$D$25,"Benchmark",$W$2:$W$25,">"&W6)) -> 5 | C6: Bissell | D6: Benchmark | E6: Brand & maker | F6: Salesforce Commerce | G6: Grand Rapids, MI | H6: https://www.bissell.com | I6: 2026-09-28 | J6: =IFERROR(SUMIFS(Checks!$F$2:$F$1297,Checks!$A$2:$A$1297,$C6,Checks!$C$2:$C$1297,"F")/(2*COUNTIFS(Checks!$A$2:$A$1297,$C6,Checks!$C$2:$C$1297,"F",Checks!$F$2:$F$1297,">=0")),"") -> 1 | K6: =COUNTIFS(Checks!$A$2:$A$1297,$C6,Checks!$C$2:$C$1297,"F",Checks!$F$2:$F$1297,">=0") -> 7 | L6: =IFERROR(SUMIFS(Checks!$F$2:$F$1297,Checks!$A$2:$A$1297,$C6,Checks!$C$2:$C$1297,"C")/(2*COUNTIFS(Checks!$A$2:$A$1297,$C6,Checks!$C$2:$C$1297,"C",Checks!$F$2:$F$1297,">=0")),"") -> 0.8125 | M6: =COUNTIFS(Checks!$A$2:$A$1297,$C6,Checks!$C$2:$C$1297,"C",Checks!$F$2:$F$1297,">=0") -> 8 | N6: =IFERROR(SUMIFS(Checks!$F$2:$F$1297,Checks!$A$2:$A$1297,$C6,Checks!$C$2:$C$1297,"B")/(2*COUNTIFS(Checks!$A$2:$A$1297,$C6,Checks!$C$2:$C$1297,"B",Checks!$F$2:$F$1297,">=0")),"") -> 0.83333333 | O6: =COUNTIFS(Checks!$A$2:$A$1297,$C6,Checks!$C$2:$C$1297,"B",Checks!$F$2:$F$1297,">=0") -> 3 | P6: =IFERROR(SUMIFS(Checks!$F$2:$F$1297,Checks!$A$2:$A$1297,$C6,Checks!$C$2:$C$1297,"T")/(2*COUNTIFS(Checks!$A$2:$A$1297,$C6,Checks!$C$2:$C$1297,"T",Checks!$F$2:$F$1297,">=0")),"") -> 1 | Q6: =COUNTIFS(Checks!$A$2:$A$1297,$C6,Checks!$C$2:$C$1297,"T",Checks!$F$2:$F$1297,">=0") -> 4 | R6: =IFERROR(SUMIFS(Checks!$F$2:$F$1297,Checks!$A$2:$A$1297,$C6,Checks!$C$2:$C$1297,"N")/(2*COUNTIFS(Checks!$A$2:$A$1297,$C6,Checks!$C$2:$C$1297,"N",Checks!$F$2:$F$1297,">=0")),"") -> 0.75 | S6: =COUNTIFS(Checks!$A$2:$A$1297,$C6,Checks!$C$2:$C$1297,"N",Checks!$F$2:$F$1297,">=0") -> 2 | T6: =K6+M6+O6+Q6+S6 -> 24 | U6: =T6/29 -> 0.82758621 | V6: =IF(T6>=26,"High",IF(T6>=20,"Medium","Low")) -> Medium | W6: =IF((IF(K6>0,Rubric!$C$3,0)+IF(M6>0,Rubric!$C$4,0)+IF(O6>0,Rubric!$C$5,0)+IF(Q6>0,Rubric!$C$6,0)+IF(S6>0,Rubric!$C$7,0))=0,"",ROUND(100*(IF(K6>0,Rubric!$C$3*J6,0)+IF(M6>0,Rubric!$C$4*L6,0)+IF(O6>0,Rubric!$C$5*N6,0)+IF(Q6>0,Rubric!$C$6*P6,0)+IF(S6>0,Rubric!$C$7*R6,0))/(IF(K6>0,Rubric!$C$3,0)+IF(M6>0,Rubric!$C$4,0)+IF(O6>0,Rubric!$C$5,0)+IF(Q6>0,Rubric!$C$6,0)+IF(S6>0,Rubric!$C$7,0)),1)) -> 88.5 | X6: =IF(W6="","",IF(W6>=Rubric!$C$11,"A",IF(W6>=Rubric!$C$12,"B",IF(W6>=Rubric!$C$13,"C",IF(W6>=Rubric!$C$14,"D","F"))))) -> A | Y6: =IF(X6="","",IF(X6="A","Benchmark",IF(X6="B","Strong",IF(X6="C","Developing",IF(X6="D","Needs work","At risk"))))) -> Benchmark | Z6: =IF(COUNT(J6,L6,N6,P6,R6)=0,"",INDEX({"Findability","Catalog","Buy","Trust","Content"},MATCH(MIN(J6,L6,N6,P6,R6),CHOOSE({1,2,3,4,5},J6,L6,N6,P6,R6),0))) -> Content | AB6: HQ confirmed via Terms/Privacy: BISSELL Homecare, Inc., 2345 Walker Avenue NW, Grand Rapids, MI 49544. support.bissell.com is robots-disallowed for fetchers. robots.txt blocks ClaudeBot, GPTBot, Google-Extended, Applebot-Extended, Meta-ExternalAgent. Social icons not present in fetched footer text.
A7: =IF(W7="","",RANK(W7,$W$2:$W$25,0)) -> 7 | B7: =IF(W7="","",1+COUNTIFS($D$2:$D$25,"Benchmark",$W$2:$W$25,">"&W7)) -> 6 | C7: La-Z-Boy | D7: Benchmark | E7: Brand & maker | F7: Custom | G7: Monroe, MI | H7: https://www.la-z-boy.com | I7: 2026-09-28 | J7: =IFERROR(SUMIFS(Checks!$F$2:$F$1297,Checks!$A$2:$A$1297,$C7,Checks!$C$2:$C$1297,"F")/(2*COUNTIFS(Checks!$A$2:$A$1297,$C7,Checks!$C$2:$C$1297,"F",Checks!$F$2:$F$1297,">=0")),"") -> 0.85714286 | K7: =COUNTIFS(Checks!$A$2:$A$1297,$C7,Checks!$C$2:$C$1297,"F",Checks!$F$2:$F$1297,">=0") -> 7 | L7: =IFERROR(SUMIFS(Checks!$F$2:$F$1297,Checks!$A$2:$A$1297,$C7,Checks!$C$2:$C$1297,"C")/(2*COUNTIFS(Checks!$A$2:$A$1297,$C7,Checks!$C$2:$C$1297,"C",Checks!$F$2:$F$1297,">=0")),"") -> 0.9375 | M7: =COUNTIFS(Checks!$A$2:$A$1297,$C7,Checks!$C$2:$C$1297,"C",Checks!$F$2:$F$1297,">=0") -> 8 | N7: =IFERROR(SUMIFS(Checks!$F$2:$F$1297,Checks!$A$2:$A$1297,$C7,Checks!$C$2:$C$1297,"B")/(2*COUNTIFS(Checks!$A$2:$A$1297,$C7,Checks!$C$2:$C$1297,"B",Checks!$F$2:$F$1297,">=0")),"") -> 0.875 | O7: =COUNTIFS(Checks!$A$2:$A$1297,$C7,Checks!$C$2:$C$1297,"B",Checks!$F$2:$F$1297,">=0") -> 4 | P7: =IFERROR(SUMIFS(Checks!$F$2:$F$1297,Checks!$A$2:$A$1297,$C7,Checks!$C$2:$C$1297,"T")/(2*COUNTIFS(Checks!$A$2:$A$1297,$C7,Checks!$C$2:$C$1297,"T",Checks!$F$2:$F$1297,">=0")),"") -> 0.9 | Q7: =COUNTIFS(Checks!$A$2:$A$1297,$C7,Checks!$C$2:$C$1297,"T",Checks!$F$2:$F$1297,">=0") -> 5 | R7: =IFERROR(SUMIFS(Checks!$F$2:$F$1297,Checks!$A$2:$A$1297,$C7,Checks!$C$2:$C$1297,"N")/(2*COUNTIFS(Checks!$A$2:$A$1297,$C7,Checks!$C$2:$C$1297,"N",Checks!$F$2:$F$1297,">=0")),"") -> 0.66666667 | S7: =COUNTIFS(Checks!$A$2:$A$1297,$C7,Checks!$C$2:$C$1297,"N",Checks!$F$2:$F$1297,">=0") -> 3 | T7: =K7+M7+O7+Q7+S7 -> 27 | U7: =T7/29 -> 0.93103448 | V7: =IF(T7>=26,"High",IF(T7>=20,"Medium","Low")) -> High | W7: =IF((IF(K7>0,Rubric!$C$3,0)+IF(M7>0,Rubric!$C$4,0)+IF(O7>0,Rubric!$C$5,0)+IF(Q7>0,Rubric!$C$6,0)+IF(S7>0,Rubric!$C$7,0))=0,"",ROUND(100*(IF(K7>0,Rubric!$C$3*J7,0)+IF(M7>0,Rubric!$C$4*L7,0)+IF(O7>0,Rubric!$C$5*N7,0)+IF(Q7>0,Rubric!$C$6*P7,0)+IF(S7>0,Rubric!$C$7*R7,0))/(IF(K7>0,Rubric!$C$3,0)+IF(M7>0,Rubric!$C$4,0)+IF(O7>0,Rubric!$C$5,0)+IF(Q7>0,Rubric!$C$6,0)+IF(S7>0,Rubric!$C$7,0)),1)) -> 87.2 | X7: =IF(W7="","",IF(W7>=Rubric!$C$11,"A",IF(W7>=Rubric!$C$12,"B",IF(W7>=Rubric!$C$13,"C",IF(W7>=Rubric!$C$14,"D","F"))))) -> A | Y7: =IF(X7="","",IF(X7="A","Benchmark",IF(X7="B","Strong",IF(X7="C","Developing",IF(X7="D","Needs work","At risk"))))) -> Benchmark | Z7: =IF(COUNT(J7,L7,N7,P7,R7)=0,"",INDEX({"Findability","Catalog","Buy","Trust","Content"},MATCH(MIN(J7,L7,N7,P7,R7),CHOOSE({1,2,3,4,5},J7,L7,N7,P7,R7),0))) -> Content | AB7: HQ confirmed as One La-Z-Boy Drive, Monroe, MI 48162 (Privacy Notice); homepage/contact default to the Columbus, OH gallery store. Exa fallback hit an Akamai 'Client Challenge'; WebFetch worked. Return policy is strict (3-day window, up to 30% restocking) and is not linked from the PDP itself.
A8: =IF(W8="","",RANK(W8,$W$2:$W$25,0)) -> 8 | B8: =IF(W8="","",1+COUNTIFS($D$2:$D$25,"Benchmark",$W$2:$W$25,">"&W8)) -> 7 | C8: Shinola | D8: Benchmark | E8: Brand & maker | F8: Shopify | G8: Detroit, MI | H8: https://www.shinola.com | I8: 2026-09-28 | J8: =IFERROR(SUMIFS(Checks!$F$2:$F$1297,Checks!$A$2:$A$1297,$C8,Checks!$C$2:$C$1297,"F")/(2*COUNTIFS(Checks!$A$2:$A$1297,$C8,Checks!$C$2:$C$1297,"F",Checks!$F$2:$F$1297,">=0")),"") -> 0.92857143 | K8: =COUNTIFS(Checks!$A$2:$A$1297,$C8,Checks!$C$2:$C$1297,"F",Checks!$F$2:$F$1297,">=0") -> 7 | L8: =IFERROR(SUMIFS(Checks!$F$2:$F$1297,Checks!$A$2:$A$1297,$C8,Checks!$C$2:$C$1297,"C")/(2*COUNTIFS(Checks!$A$2:$A$1297,$C8,Checks!$C$2:$C$1297,"C",Checks!$F$2:$F$1297,">=0")),"") -> 0.8125 | M8: =COUNTIFS(Checks!$A$2:$A$1297,$C8,Checks!$C$2:$C$1297,"C",Checks!$F$2:$F$1297,">=0") -> 8 | N8: =IFERROR(SUMIFS(Checks!$F$2:$F$1297,Checks!$A$2:$A$1297,$C8,Checks!$C$2:$C$1297,"B")/(2*COUNTIFS(Checks!$A$2:$A$1297,$C8,Checks!$C$2:$C$1297,"B",Checks!$F$2:$F$1297,">=0")),"") -> 0.875 | O8: =COUNTIFS(Checks!$A$2:$A$1297,$C8,Checks!$C$2:$C$1297,"B",Checks!$F$2:$F$1297,">=0") -> 4 | P8: =IFERROR(SUMIFS(Checks!$F$2:$F$1297,Checks!$A$2:$A$1297,$C8,Checks!$C$2:$C$1297,"T")/(2*COUNTIFS(Checks!$A$2:$A$1297,$C8,Checks!$C$2:$C$1297,"T",Checks!$F$2:$F$1297,">=0")),"") -> 1 | Q8: =COUNTIFS(Checks!$A$2:$A$1297,$C8,Checks!$C$2:$C$1297,"T",Checks!$F$2:$F$1297,">=0") -> 4 | R8: =IFERROR(SUMIFS(Checks!$F$2:$F$1297,Checks!$A$2:$A$1297,$C8,Checks!$C$2:$C$1297,"N")/(2*COUNTIFS(Checks!$A$2:$A$1297,$C8,Checks!$C$2:$C$1297,"N",Checks!$F$2:$F$1297,">=0")),"") -> 0.66666667 | S8: =COUNTIFS(Checks!$A$2:$A$1297,$C8,Checks!$C$2:$C$1297,"N",Checks!$F$2:$F$1297,">=0") -> 3 | T8: =K8+M8+O8+Q8+S8 -> 26 | U8: =T8/29 -> 0.89655172 | V8: =IF(T8>=26,"High",IF(T8>=20,"Medium","Low")) -> High | W8: =IF((IF(K8>0,Rubric!$C$3,0)+IF(M8>0,Rubric!$C$4,0)+IF(O8>0,Rubric!$C$5,0)+IF(Q8>0,Rubric!$C$6,0)+IF(S8>0,Rubric!$C$7,0))=0,"",ROUND(100*(IF(K8>0,Rubric!$C$3*J8,0)+IF(M8>0,Rubric!$C$4*L8,0)+IF(O8>0,Rubric!$C$5*N8,0)+IF(Q8>0,Rubric!$C$6*P8,0)+IF(S8>0,Rubric!$C$7*R8,0))/(IF(K8>0,Rubric!$C$3,0)+IF(M8>0,Rubric!$C$4,0)+IF(O8>0,Rubric!$C$5,0)+IF(Q8>0,Rubric!$C$6,0)+IF(S8>0,Rubric!$C$7,0)),1)) -> 86.8 | X8: =IF(W8="","",IF(W8>=Rubric!$C$11,"A",IF(W8>=Rubric!$C$12,"B",IF(W8>=Rubric!$C$13,"C",IF(W8>=Rubric!$C$14,"D","F"))))) -> A | Y8: =IF(X8="","",IF(X8="A","Benchmark",IF(X8="B","Strong",IF(X8="C","Developing",IF(X8="D","Needs work","At risk"))))) -> Benchmark | Z8: =IF(COUNT(J8,L8,N8,P8,R8)=0,"",INDEX({"Findability","Catalog","Buy","Trust","Content"},MATCH(MIN(J8,L8,N8,P8,R8),CHOOSE({1,2,3,4,5},J8,L8,N8,P8,R8),0))) -> Content | AB8: Collection/search product grids and Stockist store locator render client-side; fetchers saw 'No products found' although subcollections report counts (Men's Watches 134). HQ address 485 W. Milwaukee Ave, Detroit from Terms of Use. /pages/shinola-guarantee shows a theme 'This page is protected' notice. Social links not present in fetched footer text (icon links may be stripped).
A9: =IF(W9="","",RANK(W9,$W$2:$W$25,0)) -> 9 | B9: =IF(W9="","",1+COUNTIFS($D$2:$D$25,"Benchmark",$W$2:$W$25,">"&W9)) -> 8 | C9: Zingerman's Mail Order | D9: Benchmark | E9: Food & drink maker | F9: Custom | G9: Ann Arbor, MI | H9: https://www.zingermans.com | I9: 2026-09-28 | J9: =IFERROR(SUMIFS(Checks!$F$2:$F$1297,Checks!$A$2:$A$1297,$C9,Checks!$C$2:$C$1297,"F")/(2*COUNTIFS(Checks!$A$2:$A$1297,$C9,Checks!$C$2:$C$1297,"F",Checks!$F$2:$F$1297,">=0")),"") -> 0.85714286 | K9: =COUNTIFS(Checks!$A$2:$A$1297,$C9,Checks!$C$2:$C$1297,"F",Checks!$F$2:$F$1297,">=0") -> 7 | L9: =IFERROR(SUMIFS(Checks!$F$2:$F$1297,Checks!$A$2:$A$1297,$C9,Checks!$C$2:$C$1297,"C")/(2*COUNTIFS(Checks!$A$2:$A$1297,$C9,Checks!$C$2:$C$1297,"C",Checks!$F$2:$F$1297,">=0")),"") -> 0.85714286 | M9: =COUNTIFS(Checks!$A$2:$A$1297,$C9,Checks!$C$2:$C$1297,"C",Checks!$F$2:$F$1297,">=0") -> 7 | N9: =IFERROR(SUMIFS(Checks!$F$2:$F$1297,Checks!$A$2:$A$1297,$C9,Checks!$C$2:$C$1297,"B")/(2*COUNTIFS(Checks!$A$2:$A$1297,$C9,Checks!$C$2:$C$1297,"B",Checks!$F$2:$F$1297,">=0")),"") -> 0.9 | O9: =COUNTIFS(Checks!$A$2:$A$1297,$C9,Checks!$C$2:$C$1297,"B",Checks!$F$2:$F$1297,">=0") -> 5 | P9: =IFERROR(SUMIFS(Checks!$F$2:$F$1297,Checks!$A$2:$A$1297,$C9,Checks!$C$2:$C$1297,"T")/(2*COUNTIFS(Checks!$A$2:$A$1297,$C9,Checks!$C$2:$C$1297,"T",Checks!$F$2:$F$1297,">=0")),"") -> 0.9 | Q9: =COUNTIFS(Checks!$A$2:$A$1297,$C9,Checks!$C$2:$C$1297,"T",Checks!$F$2:$F$1297,">=0") -> 5 | R9: =IFERROR(SUMIFS(Checks!$F$2:$F$1297,Checks!$A$2:$A$1297,$C9,Checks!$C$2:$C$1297,"N")/(2*COUNTIFS(Checks!$A$2:$A$1297,$C9,Checks!$C$2:$C$1297,"N",Checks!$F$2:$F$1297,">=0")),"") -> 0.66666667 | S9: =COUNTIFS(Checks!$A$2:$A$1297,$C9,Checks!$C$2:$C$1297,"N",Checks!$F$2:$F$1297,">=0") -> 3 | T9: =K9+M9+O9+Q9+S9 -> 27 | U9: =T9/29 -> 0.93103448 | V9: =IF(T9>=26,"High",IF(T9>=20,"Medium","Low")) -> High | W9: =IF((IF(K9>0,Rubric!$C$3,0)+IF(M9>0,Rubric!$C$4,0)+IF(O9>0,Rubric!$C$5,0)+IF(Q9>0,Rubric!$C$6,0)+IF(S9>0,Rubric!$C$7,0))=0,"",ROUND(100*(IF(K9>0,Rubric!$C$3*J9,0)+IF(M9>0,Rubric!$C$4*L9,0)+IF(O9>0,Rubric!$C$5*N9,0)+IF(Q9>0,Rubric!$C$6*P9,0)+IF(S9>0,Rubric!$C$7*R9,0))/(IF(K9>0,Rubric!$C$3,0)+IF(M9>0,Rubric!$C$4,0)+IF(O9>0,Rubric!$C$5,0)+IF(Q9>0,Rubric!$C$6,0)+IF(S9>0,Rubric!$C$7,0)),1)) -> 85.3 | X9: =IF(W9="","",IF(W9>=Rubric!$C$11,"A",IF(W9>=Rubric!$C$12,"B",IF(W9>=Rubric!$C$13,"C",IF(W9>=Rubric!$C$14,"D","F"))))) -> A | Y9: =IF(X9="","",IF(X9="A","Benchmark",IF(X9="B","Strong",IF(X9="C","Developing",IF(X9="D","Needs work","At risk"))))) -> Benchmark | Z9: =IF(COUNT(J9,L9,N9,P9,R9)=0,"",INDEX({"Findability","Catalog","Buy","Trust","Content"},MATCH(MIN(J9,L9,N9,P9,R9),CHOOSE({1,2,3,4,5},J9,L9,N9,P9,R9),0))) -> Content | AB9: Custom ASP.NET platform (Category.aspx, sitemap.aspx). Category URLs are query strings. No Terms page found; privacy policy lives on zingermanscommunity.com.
A10: =IF(W10="","",RANK(W10,$W$2:$W$25,0)) -> 10 | B10: =IF(W10="","",1+COUNTIFS($D$2:$D$25,"Benchmark",$W$2:$W$25,">"&W10)) -> 9 | C10: Dunham's Sports | D10: Benchmark | E10: Retail chain | F10: Custom | G10: Troy, MI | H10: https://www.dunhamssports.com | I10: 2026-09-28 | J10: =IFERROR(SUMIFS(Checks!$F$2:$F$1297,Checks!$A$2:$A$1297,$C10,Checks!$C$2:$C$1297,"F")/(2*COUNTIFS(Checks!$A$2:$A$1297,$C10,Checks!$C$2:$C$1297,"F",Checks!$F$2:$F$1297,">=0")),"") -> 0.85714286 | K10: =COUNTIFS(Checks!$A$2:$A$1297,$C10,Checks!$C$2:$C$1297,"F",Checks!$F$2:$F$1297,">=0") -> 7 | L10: =IFERROR(SUMIFS(Checks!$F$2:$F$1297,Checks!$A$2:$A$1297,$C10,Checks!$C$2:$C$1297,"C")/(2*COUNTIFS(Checks!$A$2:$A$1297,$C10,Checks!$C$2:$C$1297,"C",Checks!$F$2:$F$1297,">=0")),"") -> 0.78571429 | M10: =COUNTIFS(Checks!$A$2:$A$1297,$C10,Checks!$C$2:$C$1297,"C",Checks!$F$2:$F$1297,">=0") -> 7 | N10: =IFERROR(SUMIFS(Checks!$F$2:$F$1297,Checks!$A$2:$A$1297,$C10,Checks!$C$2:$C$1297,"B")/(2*COUNTIFS(Checks!$A$2:$A$1297,$C10,Checks!$C$2:$C$1297,"B",Checks!$F$2:$F$1297,">=0")),"") -> 0.75 | O10: =COUNTIFS(Checks!$A$2:$A$1297,$C10,Checks!$C$2:$C$1297,"B",Checks!$F$2:$F$1297,">=0") -> 4 | P10: =IFERROR(SUMIFS(Checks!$F$2:$F$1297,Checks!$A$2:$A$1297,$C10,Checks!$C$2:$C$1297,"T")/(2*COUNTIFS(Checks!$A$2:$A$1297,$C10,Checks!$C$2:$C$1297,"T",Checks!$F$2:$F$1297,">=0")),"") -> 1 | Q10: =COUNTIFS(Checks!$A$2:$A$1297,$C10,Checks!$C$2:$C$1297,"T",Checks!$F$2:$F$1297,">=0") -> 4 | R10: =IFERROR(SUMIFS(Checks!$F$2:$F$1297,Checks!$A$2:$A$1297,$C10,Checks!$C$2:$C$1297,"N")/(2*COUNTIFS(Checks!$A$2:$A$1297,$C10,Checks!$C$2:$C$1297,"N",Checks!$F$2:$F$1297,">=0")),"") -> 0.66666667 | S10: =COUNTIFS(Checks!$A$2:$A$1297,$C10,Checks!$C$2:$C$1297,"N",Checks!$F$2:$F$1297,">=0") -> 3 | T10: =K10+M10+O10+Q10+S10 -> 25 | U10: =T10/29 -> 0.86206897 | V10: =IF(T10>=26,"High",IF(T10>=20,"Medium","Low")) -> Medium | W10: =IF((IF(K10>0,Rubric!$C$3,0)+IF(M10>0,Rubric!$C$4,0)+IF(O10>0,Rubric!$C$5,0)+IF(Q10>0,Rubric!$C$6,0)+IF(S10>0,Rubric!$C$7,0))=0,"",ROUND(100*(IF(K10>0,Rubric!$C$3*J10,0)+IF(M10>0,Rubric!$C$4*L10,0)+IF(O10>0,Rubric!$C$5*N10,0)+IF(Q10>0,Rubric!$C$6*P10,0)+IF(S10>0,Rubric!$C$7*R10,0))/(IF(K10>0,Rubric!$C$3,0)+IF(M10>0,Rubric!$C$4,0)+IF(O10>0,Rubric!$C$5,0)+IF(Q10>0,Rubric!$C$6,0)+IF(S10>0,Rubric!$C$7,0)),1)) -> 81.7 | X10: =IF(W10="","",IF(W10>=Rubric!$C$11,"A",IF(W10>=Rubric!$C$12,"B",IF(W10>=Rubric!$C$13,"C",IF(W10>=Rubric!$C$14,"D","F"))))) -> B | Y10: =IF(X10="","",IF(X10="A","Benchmark",IF(X10="B","Strong",IF(X10="C","Developing",IF(X10="D","Needs work","At risk"))))) -> Strong | Z10: =IF(COUNT(J10,L10,N10,P10,R10)=0,"",INDEX({"Findability","Catalog","Buy","Trust","Content"},MATCH(MIN(J10,L10,N10,P10,R10),CHOOSE({1,2,3,4,5},J10,L10,N10,P10,R10),0))) -> Content | AB10: Shopware 6 storefront; the mega-menu crowds page content out of text fetches, so search box, add-to-cart label and social links could not be confirmed.
A11: =IF(W11="","",RANK(W11,$W$2:$W$25,0)) -> 11 | B11: =IF(W11="","",1+COUNTIFS($D$2:$D$25,"Benchmark",$W$2:$W$25,">"&W11)) -> 10 | C11: Apparel Wholesale Depot | D11: Benchmark | E11: Wholesale / B2B | F11: Shopify | G11: Warren, MI | H11: https://www.apparelwholesaledepot.com | I11: 2026-09-28 | J11: =IFERROR(SUMIFS(Checks!$F$2:$F$1297,Checks!$A$2:$A$1297,$C11,Checks!$C$2:$C$1297,"F")/(2*COUNTIFS(Checks!$A$2:$A$1297,$C11,Checks!$C$2:$C$1297,"F",Checks!$F$2:$F$1297,">=0")),"") -> 0.78571429 | K11: =COUNTIFS(Checks!$A$2:$A$1297,$C11,Checks!$C$2:$C$1297,"F",Checks!$F$2:$F$1297,">=0") -> 7 | L11: =IFERROR(SUMIFS(Checks!$F$2:$F$1297,Checks!$A$2:$A$1297,$C11,Checks!$C$2:$C$1297,"C")/(2*COUNTIFS(Checks!$A$2:$A$1297,$C11,Checks!$C$2:$C$1297,"C",Checks!$F$2:$F$1297,">=0")),"") -> 0.9375 | M11: =COUNTIFS(Checks!$A$2:$A$1297,$C11,Checks!$C$2:$C$1297,"C",Checks!$F$2:$F$1297,">=0") -> 8 | N11: =IFERROR(SUMIFS(Checks!$F$2:$F$1297,Checks!$A$2:$A$1297,$C11,Checks!$C$2:$C$1297,"B")/(2*COUNTIFS(Checks!$A$2:$A$1297,$C11,Checks!$C$2:$C$1297,"B",Checks!$F$2:$F$1297,">=0")),"") -> 0.6 | O11: =COUNTIFS(Checks!$A$2:$A$1297,$C11,Checks!$C$2:$C$1297,"B",Checks!$F$2:$F$1297,">=0") -> 5 | P11: =IFERROR(SUMIFS(Checks!$F$2:$F$1297,Checks!$A$2:$A$1297,$C11,Checks!$C$2:$C$1297,"T")/(2*COUNTIFS(Checks!$A$2:$A$1297,$C11,Checks!$C$2:$C$1297,"T",Checks!$F$2:$F$1297,">=0")),"") -> 1 | Q11: =COUNTIFS(Checks!$A$2:$A$1297,$C11,Checks!$C$2:$C$1297,"T",Checks!$F$2:$F$1297,">=0") -> 5 | R11: =IFERROR(SUMIFS(Checks!$F$2:$F$1297,Checks!$A$2:$A$1297,$C11,Checks!$C$2:$C$1297,"N")/(2*COUNTIFS(Checks!$A$2:$A$1297,$C11,Checks!$C$2:$C$1297,"N",Checks!$F$2:$F$1297,">=0")),"") -> 0.66666667 | S11: =COUNTIFS(Checks!$A$2:$A$1297,$C11,Checks!$C$2:$C$1297,"N",Checks!$F$2:$F$1297,">=0") -> 3 | T11: =K11+M11+O11+Q11+S11 -> 28 | U11: =T11/29 -> 0.96551724 | V11: =IF(T11>=26,"High",IF(T11>=20,"Medium","Low")) -> High | W11: =IF((IF(K11>0,Rubric!$C$3,0)+IF(M11>0,Rubric!$C$4,0)+IF(O11>0,Rubric!$C$5,0)+IF(Q11>0,Rubric!$C$6,0)+IF(S11>0,Rubric!$C$7,0))=0,"",ROUND(100*(IF(K11>0,Rubric!$C$3*J11,0)+IF(M11>0,Rubric!$C$4*L11,0)+IF(O11>0,Rubric!$C$5*N11,0)+IF(Q11>0,Rubric!$C$6*P11,0)+IF(S11>0,Rubric!$C$7*R11,0))/(IF(K11>0,Rubric!$C$3,0)+IF(M11>0,Rubric!$C$4,0)+IF(O11>0,Rubric!$C$5,0)+IF(Q11>0,Rubric!$C$6,0)+IF(S11>0,Rubric!$C$7,0)),1)) -> 81.4 | X11: =IF(W11="","",IF(W11>=Rubric!$C$11,"A",IF(W11>=Rubric!$C$12,"B",IF(W11>=Rubric!$C$13,"C",IF(W11>=Rubric!$C$14,"D","F"))))) -> B | Y11: =IF(X11="","",IF(X11="A","Benchmark",IF(X11="B","Strong",IF(X11="C","Developing",IF(X11="D","Needs work","At risk"))))) -> Strong | Z11: =IF(COUNT(J11,L11,N11,P11,R11)=0,"",INDEX({"Findability","Catalog","Buy","Trust","Content"},MATCH(MIN(J11,L11,N11,P11,R11),CHOOSE({1,2,3,4,5},J11,L11,N11,P11,R11),0))) -> Buy | AB11: Single-location wholesaler with a retail-style Shopify checkout; wholesale pricing is phone-only. /pages/contact returns 404 (the live page is /pages/contact-us). Homepage canonical and meta description were not returned in two separate fetches while product and collection pages showed both.
A12: =IF(W12="","",RANK(W12,$W$2:$W$25,0)) -> 12 | B12: =IF(W12="","",1+COUNTIFS($D$2:$D$25,"Benchmark",$W$2:$W$25,">"&W12)) -> 11 | C12: Made In Detroit | D12: Benchmark | E12: Brand & maker | F12: Shopify | G12: Clarkston, MI | H12: https://www.madeindetroit.com | I12: 2026-09-28 | J12: =IFERROR(SUMIFS(Checks!$F$2:$F$1297,Checks!$A$2:$A$1297,$C12,Checks!$C$2:$C$1297,"F")/(2*COUNTIFS(Checks!$A$2:$A$1297,$C12,Checks!$C$2:$C$1297,"F",Checks!$F$2:$F$1297,">=0")),"") -> 1 | K12: =COUNTIFS(Checks!$A$2:$A$1297,$C12,Checks!$C$2:$C$1297,"F",Checks!$F$2:$F$1297,">=0") -> 7 | L12: =IFERROR(SUMIFS(Checks!$F$2:$F$1297,Checks!$A$2:$A$1297,$C12,Checks!$C$2:$C$1297,"C")/(2*COUNTIFS(Checks!$A$2:$A$1297,$C12,Checks!$C$2:$C$1297,"C",Checks!$F$2:$F$1297,">=0")),"") -> 0.75 | M12: =COUNTIFS(Checks!$A$2:$A$1297,$C12,Checks!$C$2:$C$1297,"C",Checks!$F$2:$F$1297,">=0") -> 8 | N12: =IFERROR(SUMIFS(Checks!$F$2:$F$1297,Checks!$A$2:$A$1297,$C12,Checks!$C$2:$C$1297,"B")/(2*COUNTIFS(Checks!$A$2:$A$1297,$C12,Checks!$C$2:$C$1297,"B",Checks!$F$2:$F$1297,">=0")),"") -> 0.75 | O12: =COUNTIFS(Checks!$A$2:$A$1297,$C12,Checks!$C$2:$C$1297,"B",Checks!$F$2:$F$1297,">=0") -> 4 | P12: =IFERROR(SUMIFS(Checks!$F$2:$F$1297,Checks!$A$2:$A$1297,$C12,Checks!$C$2:$C$1297,"T")/(2*COUNTIFS(Checks!$A$2:$A$1297,$C12,Checks!$C$2:$C$1297,"T",Checks!$F$2:$F$1297,">=0")),"") -> 1 | Q12: =COUNTIFS(Checks!$A$2:$A$1297,$C12,Checks!$C$2:$C$1297,"T",Checks!$F$2:$F$1297,">=0") -> 4 | R12: =IFERROR(SUMIFS(Checks!$F$2:$F$1297,Checks!$A$2:$A$1297,$C12,Checks!$C$2:$C$1297,"N")/(2*COUNTIFS(Checks!$A$2:$A$1297,$C12,Checks!$C$2:$C$1297,"N",Checks!$F$2:$F$1297,">=0")),"") -> 0.33333333 | S12: =COUNTIFS(Checks!$A$2:$A$1297,$C12,Checks!$C$2:$C$1297,"N",Checks!$F$2:$F$1297,">=0") -> 3 | T12: =K12+M12+O12+Q12+S12 -> 26 | U12: =T12/29 -> 0.89655172 | V12: =IF(T12>=26,"High",IF(T12>=20,"Medium","Low")) -> High | W12: =IF((IF(K12>0,Rubric!$C$3,0)+IF(M12>0,Rubric!$C$4,0)+IF(O12>0,Rubric!$C$5,0)+IF(Q12>0,Rubric!$C$6,0)+IF(S12>0,Rubric!$C$7,0))=0,"",ROUND(100*(IF(K12>0,Rubric!$C$3*J12,0)+IF(M12>0,Rubric!$C$4*L12,0)+IF(O12>0,Rubric!$C$5*N12,0)+IF(Q12>0,Rubric!$C$6*P12,0)+IF(S12>0,Rubric!$C$7*R12,0))/(IF(K12>0,Rubric!$C$3,0)+IF(M12>0,Rubric!$C$4,0)+IF(O12>0,Rubric!$C$5,0)+IF(Q12>0,Rubric!$C$6,0)+IF(S12>0,Rubric!$C$7,0)),1)) -> 80.8 | X12: =IF(W12="","",IF(W12>=Rubric!$C$11,"A",IF(W12>=Rubric!$C$12,"B",IF(W12>=Rubric!$C$13,"C",IF(W12>=Rubric!$C$14,"D","F"))))) -> B | Y12: =IF(X12="","",IF(X12="A","Benchmark",IF(X12="B","Strong",IF(X12="C","Developing",IF(X12="D","Needs work","At risk"))))) -> Strong | Z12: =IF(COUNT(J12,L12,N12,P12,R12)=0,"",INDEX({"Findability","Catalog","Buy","Trust","Content"},MATCH(MIN(J12,L12,N12,P12,R12),CHOOSE({1,2,3,4,5},J12,L12,N12,P12,R12),0))) -> Content | AB12: Company is Bobby Moscow, LLC at 5799 Terex, Clarkston, MI 48346 (metro Detroit) per Privacy and Return pages; the site itself only names Detroit as its origin. Social profile links not present in fetched footer text on three pages.
A13: =IF(W13="","",RANK(W13,$W$2:$W$25,0)) -> 14 | B13: =IF(W13="","",1+COUNTIFS($D$2:$D$25,"Benchmark",$W$2:$W$25,">"&W13)) -> 12 | C13: English Gardens | D13: Benchmark | E13: Retail chain | F13: WooCommerce | G13: Dearborn Heights, MI | H13: https://www.englishgardens.com | I13: 2026-09-28 | J13: =IFERROR(SUMIFS(Checks!$F$2:$F$1297,Checks!$A$2:$A$1297,$C13,Checks!$C$2:$C$1297,"F")/(2*COUNTIFS(Checks!$A$2:$A$1297,$C13,Checks!$C$2:$C$1297,"F",Checks!$F$2:$F$1297,">=0")),"") -> 0.85714286 | K13: =COUNTIFS(Checks!$A$2:$A$1297,$C13,Checks!$C$2:$C$1297,"F",Checks!$F$2:$F$1297,">=0") -> 7 | L13: =IFERROR(SUMIFS(Checks!$F$2:$F$1297,Checks!$A$2:$A$1297,$C13,Checks!$C$2:$C$1297,"C")/(2*COUNTIFS(Checks!$A$2:$A$1297,$C13,Checks!$C$2:$C$1297,"C",Checks!$F$2:$F$1297,">=0")),"") -> 0.625 | M13: =COUNTIFS(Checks!$A$2:$A$1297,$C13,Checks!$C$2:$C$1297,"C",Checks!$F$2:$F$1297,">=0") -> 8 | N13: =IFERROR(SUMIFS(Checks!$F$2:$F$1297,Checks!$A$2:$A$1297,$C13,Checks!$C$2:$C$1297,"B")/(2*COUNTIFS(Checks!$A$2:$A$1297,$C13,Checks!$C$2:$C$1297,"B",Checks!$F$2:$F$1297,">=0")),"") -> 0.75 | O13: =COUNTIFS(Checks!$A$2:$A$1297,$C13,Checks!$C$2:$C$1297,"B",Checks!$F$2:$F$1297,">=0") -> 4 | P13: =IFERROR(SUMIFS(Checks!$F$2:$F$1297,Checks!$A$2:$A$1297,$C13,Checks!$C$2:$C$1297,"T")/(2*COUNTIFS(Checks!$A$2:$A$1297,$C13,Checks!$C$2:$C$1297,"T",Checks!$F$2:$F$1297,">=0")),"") -> 0.75 | Q13: =COUNTIFS(Checks!$A$2:$A$1297,$C13,Checks!$C$2:$C$1297,"T",Checks!$F$2:$F$1297,">=0") -> 4 | R13: =IFERROR(SUMIFS(Checks!$F$2:$F$1297,Checks!$A$2:$A$1297,$C13,Checks!$C$2:$C$1297,"N")/(2*COUNTIFS(Checks!$A$2:$A$1297,$C13,Checks!$C$2:$C$1297,"N",Checks!$F$2:$F$1297,">=0")),"") -> 1 | S13: =COUNTIFS(Checks!$A$2:$A$1297,$C13,Checks!$C$2:$C$1297,"N",Checks!$F$2:$F$1297,">=0") -> 3 | T13: =K13+M13+O13+Q13+S13 -> 26 | U13: =T13/29 -> 0.89655172 | V13: =IF(T13>=26,"High",IF(T13>=20,"Medium","Low")) -> High | W13: =IF((IF(K13>0,Rubric!$C$3,0)+IF(M13>0,Rubric!$C$4,0)+IF(O13>0,Rubric!$C$5,0)+IF(Q13>0,Rubric!$C$6,0)+IF(S13>0,Rubric!$C$7,0))=0,"",ROUND(100*(IF(K13>0,Rubric!$C$3*J13,0)+IF(M13>0,Rubric!$C$4*L13,0)+IF(O13>0,Rubric!$C$5*N13,0)+IF(Q13>0,Rubric!$C$6*P13,0)+IF(S13>0,Rubric!$C$7*R13,0))/(IF(K13>0,Rubric!$C$3,0)+IF(M13>0,Rubric!$C$4,0)+IF(O13>0,Rubric!$C$5,0)+IF(Q13>0,Rubric!$C$6,0)+IF(S13>0,Rubric!$C$7,0)),1)) -> 76.4 | X13: =IF(W13="","",IF(W13>=Rubric!$C$11,"A",IF(W13>=Rubric!$C$12,"B",IF(W13>=Rubric!$C$13,"C",IF(W13>=Rubric!$C$14,"D","F"))))) -> B | Y13: =IF(X13="","",IF(X13="A","Benchmark",IF(X13="B","Strong",IF(X13="C","Developing",IF(X13="D","Needs work","At risk"))))) -> Strong | Z13: =IF(COUNT(J13,L13,N13,P13,R13)=0,"",INDEX({"Findability","Catalog","Buy","Trust","Content"},MATCH(MIN(J13,L13,N13,P13,R13),CHOOSE({1,2,3,4,5},J13,L13,N13,P13,R13),0))) -> Catalog | AB13: WooCommerce + Elementor 4.2.4 + Yoast. Corporate office page confirms 22650 Ford Rd, Dearborn Heights.
... A22: =IF(W22="","",RANK(W22,$W$2:$W$25,0)) -> 24 | B22: =IF(W22="","",1+COUNTIFS($D$2:$D$25,"Benchmark",$W$2:$W$25,">"&W22)) -> 21 | C22: Sun Valley Foods | D22: Benchmark | E22: Wholesale / B2B | F22: Custom | G22: Detroit, MI | H22: https://www.sunvalleyfoods.com | I22: 2026-09-28 | J22: =IFERROR(SUMIFS(Checks!$F$2:$F$1297,Checks!$A$2:$A$1297,$C22,Checks!$C$2:$C$1297,"F")/(2*COUNTIFS(Checks!$A$2:$A$1297,$C22,Checks!$C$2:$C$1297,"F",Checks!$F$2:$F$1297,">=0")),"") -> 0.64285714 | K22: =COUNTIFS(Checks!$A$2:$A$1297,$C22,Checks!$C$2:$C$1297,"F",Checks!$F$2:$F$1297,">=0") -> 7 | L22: =IFERROR(SUMIFS(Checks!$F$2:$F$1297,Checks!$A$2:$A$1297,$C22,Checks!$C$2:$C$1297,"C")/(2*COUNTIFS(Checks!$A$2:$A$1297,$C22,Checks!$C$2:$C$1297,"C",Checks!$F$2:$F$1297,">=0")),"") -> 0.0625 | M22: =COUNTIFS(Checks!$A$2:$A$1297,$C22,Checks!$C$2:$C$1297,"C",Checks!$F$2:$F$1297,">=0") -> 8 | N22: =IFERROR(SUMIFS(Checks!$F$2:$F$1297,Checks!$A$2:$A$1297,$C22,Checks!$C$2:$C$1297,"B")/(2*COUNTIFS(Checks!$A$2:$A$1297,$C22,Checks!$C$2:$C$1297,"B",Checks!$F$2:$F$1297,">=0")),"") -> 0.3 | O22: =COUNTIFS(Checks!$A$2:$A$1297,$C22,Checks!$C$2:$C$1297,"B",Checks!$F$2:$F$1297,">=0") -> 5 | P22: =IFERROR(SUMIFS(Checks!$F$2:$F$1297,Checks!$A$2:$A$1297,$C22,Checks!$C$2:$C$1297,"T")/(2*COUNTIFS(Checks!$A$2:$A$1297,$C22,Checks!$C$2:$C$1297,"T",Checks!$F$2:$F$1297,">=0")),"") -> 0.5 | Q22: =COUNTIFS(Checks!$A$2:$A$1297,$C22,Checks!$C$2:$C$1297,"T",Checks!$F$2:$F$1297,">=0") -> 5 | R22: =IFERROR(SUMIFS(Checks!$F$2:$F$1297,Checks!$A$2:$A$1297,$C22,Checks!$C$2:$C$1297,"N")/(2*COUNTIFS(Checks!$A$2:$A$1297,$C22,Checks!$C$2:$C$1297,"N",Checks!$F$2:$F$1297,">=0")),"") -> 0.16666667 | S22: =COUNTIFS(Checks!$A$2:$A$1297,$C22,Checks!$C$2:$C$1297,"N",Checks!$F$2:$F$1297,">=0") -> 3 | T22: =K22+M22+O22+Q22+S22 -> 28 | U22: =T22/29 -> 0.96551724 | V22: =IF(T22>=26,"High",IF(T22>=20,"Medium","Low")) -> High | W22: =IF((IF(K22>0,Rubric!$C$3,0)+IF(M22>0,Rubric!$C$4,0)+IF(O22>0,Rubric!$C$5,0)+IF(Q22>0,Rubric!$C$6,0)+IF(S22>0,Rubric!$C$7,0))=0,"",ROUND(100*(IF(K22>0,Rubric!$C$3*J22,0)+IF(M22>0,Rubric!$C$4*L22,0)+IF(O22>0,Rubric!$C$5*N22,0)+IF(Q22>0,Rubric!$C$6*P22,0)+IF(S22>0,Rubric!$C$7*R22,0))/(IF(K22>0,Rubric!$C$3,0)+IF(M22>0,Rubric!$C$4,0)+IF(O22>0,Rubric!$C$5,0)+IF(Q22>0,Rubric!$C$6,0)+IF(S22>0,Rubric!$C$7,0)),1)) -> 33.1 | X22: =IF(W22="","",IF(W22>=Rubric!$C$11,"A",IF(W22>=Rubric!$C$12,"B",IF(W22>=Rubric!$C$13,"C",IF(W22>=Rubric!$C$14,"D","F"))))) -> F | Y22: =IF(X22="","",IF(X22="A","Benchmark",IF(X22="B","Strong",IF(X22="C","Developing",IF(X22="D","Needs work","At risk"))))) -> At risk | Z22: =IF(COUNT(J22,L22,N22,P22,R22)=0,"",INDEX({"Findability","Catalog","Buy","Trust","Content"},MATCH(MIN(J22,L22,N22,P22,R22),CHOOSE({1,2,3,4,5},J22,L22,N22,P22,R22),0))) -> Catalog | AB22: Alternate used in place of UTN Wholesale. HQ is stated only on the Careers page ('equal opportunity employer based in Detroit Michigan'); no street address appears anywhere on the site. Ordering is restricted to existing customers via the /erp login.
A23: =IF(W23="","",RANK(W23,$W$2:$W$25,0)) -> 1 | B23: =IF(W23="","",1+COUNTIFS($D$2:$D$25,"Benchmark",$W$2:$W$25,">"&W23)) -> 1 | C23: Blueroot Health (storefront scored: Fairhaven Health) | D23: Target | E23: DTC brand | F23: Shopify | G23: Middletown, CT | H23: https://www.fairhavenhealth.com | I23: 2026-09-28 | J23: =IFERROR(SUMIFS(Checks!$F$2:$F$1297,Checks!$A$2:$A$1297,$C23,Checks!$C$2:$C$1297,"F")/(2*COUNTIFS(Checks!$A$2:$A$1297,$C23,Checks!$C$2:$C$1297,"F",Checks!$F$2:$F$1297,">=0")),"") -> 1 | K23: =COUNTIFS(Checks!$A$2:$A$1297,$C23,Checks!$C$2:$C$1297,"F",Checks!$F$2:$F$1297,">=0") -> 8 | L23: =IFERROR(SUMIFS(Checks!$F$2:$F$1297,Checks!$A$2:$A$1297,$C23,Checks!$C$2:$C$1297,"C")/(2*COUNTIFS(Checks!$A$2:$A$1297,$C23,Checks!$C$2:$C$1297,"C",Checks!$F$2:$F$1297,">=0")),"") -> 1 | M23: =COUNTIFS(Checks!$A$2:$A$1297,$C23,Checks!$C$2:$C$1297,"C",Checks!$F$2:$F$1297,">=0") -> 8 | N23: =IFERROR(SUMIFS(Checks!$F$2:$F$1297,Checks!$A$2:$A$1297,$C23,Checks!$C$2:$C$1297,"B")/(2*COUNTIFS(Checks!$A$2:$A$1297,$C23,Checks!$C$2:$C$1297,"B",Checks!$F$2:$F$1297,">=0")),"") -> 1 | O23: =COUNTIFS(Checks!$A$2:$A$1297,$C23,Checks!$C$2:$C$1297,"B",Checks!$F$2:$F$1297,">=0") -> 5 | P23: =IFERROR(SUMIFS(Checks!$F$2:$F$1297,Checks!$A$2:$A$1297,$C23,Checks!$C$2:$C$1297,"T")/(2*COUNTIFS(Checks!$A$2:$A$1297,$C23,Checks!$C$2:$C$1297,"T",Checks!$F$2:$F$1297,">=0")),"") -> 0.9 | Q23: =COUNTIFS(Checks!$A$2:$A$1297,$C23,Checks!$C$2:$C$1297,"T",Checks!$F$2:$F$1297,">=0") -> 5 | R23: =IFERROR(SUMIFS(Checks!$F$2:$F$1297,Checks!$A$2:$A$1297,$C23,Checks!$C$2:$C$1297,"N")/(2*COUNTIFS(Checks!$A$2:$A$1297,$C23,Checks!$C$2:$C$1297,"N",Checks!$F$2:$F$1297,">=0")),"") -> 0.66666667 | S23: =COUNTIFS(Checks!$A$2:$A$1297,$C23,Checks!$C$2:$C$1297,"N",Checks!$F$2:$F$1297,">=0") -> 3 | T23: =K23+M23+O23+Q23+S23 -> 29 | U23: =T23/29 -> 1 | V23: =IF(T23>=26,"High",IF(T23>=20,"Medium","Low")) -> High | W23: =IF((IF(K23>0,Rubric!$C$3,0)+IF(M23>0,Rubric!$C$4,0)+IF(O23>0,Rubric!$C$5,0)+IF(Q23>0,Rubric!$C$6,0)+IF(S23>0,Rubric!$C$7,0))=0,"",ROUND(100*(IF(K23>0,Rubric!$C$3*J23,0)+IF(M23>0,Rubric!$C$4*L23,0)+IF(O23>0,Rubric!$C$5*N23,0)+IF(Q23>0,Rubric!$C$6*P23,0)+IF(S23>0,Rubric!$C$7*R23,0))/(IF(K23>0,Rubric!$C$3,0)+IF(M23>0,Rubric!$C$4,0)+IF(O23>0,Rubric!$C$5,0)+IF(Q23>0,Rubric!$C$6,0)+IF(S23>0,Rubric!$C$7,0)),1)) -> 95.2 | X23: =IF(W23="","",IF(W23>=Rubric!$C$11,"A",IF(W23>=Rubric!$C$12,"B",IF(W23>=Rubric!$C$13,"C",IF(W23>=Rubric!$C$14,"D","F"))))) -> A | Y23: =IF(X23="","",IF(X23="A","Benchmark",IF(X23="B","Strong",IF(X23="C","Developing",IF(X23="D","Needs work","At risk"))))) -> Benchmark | Z23: =IF(COUNT(J23,L23,N23,P23,R23)=0,"",INDEX({"Findability","Catalog","Buy","Trust","Content"},MATCH(MIN(J23,L23,N23,P23,R23),CHOOSE({1,2,3,4,5},J23,L23,N23,P23,R23),0))) -> Content | AA23: https://mousabatarseh.com/blueroot-review/ | AB23: All 40 Fairhaven fetches returned 200 via curl (no JS-render fallback needed). Review widgets (Stamped) and the Recharge subscription widget render client-side; counts were read from server-side badge attributes (data-reviews/data-rating) and SubscriptionWidgetConfig. Checkout was not entered; B3 is based on accelerated-checkout buttons on the PDP. Blog article pages were not fetched (per-store fetch cap), so N1 reflects the undated index only. Sister stores bariatricfusion.com, vitalnutrients.co and unjury.com were sampled (17 fetches total) for Part 2 cross-brand findings only and are not scored here. Health/medical claim language was deliberately not evaluated.
A24: =IF(W24="","",RANK(W24,$W$2:$W$25,0)) -> 21 | B24: =IF(W24="","",1+COUNTIFS($D$2:$D$25,"Benchmark",$W$2:$W$25,">"&W24)) -> 19 | C24: Federal Fluid Power, Inc. | D24: Target | E24: B2B distributor | F24: Magento | G24: Plymouth, MI | H24: https://federalfp.com | I24: 2026-09-28 | J24: =IFERROR(SUMIFS(Checks!$F$2:$F$1297,Checks!$A$2:$A$1297,$C24,Checks!$C$2:$C$1297,"F")/(2*COUNTIFS(Checks!$A$2:$A$1297,$C24,Checks!$C$2:$C$1297,"F",Checks!$F$2:$F$1297,">=0")),"") -> 0.75 | K24: =COUNTIFS(Checks!$A$2:$A$1297,$C24,Checks!$C$2:$C$1297,"F",Checks!$F$2:$F$1297,">=0") -> 8 | L24: =IFERROR(SUMIFS(Checks!$F$2:$F$1297,Checks!$A$2:$A$1297,$C24,Checks!$C$2:$C$1297,"C")/(2*COUNTIFS(Checks!$A$2:$A$1297,$C24,Checks!$C$2:$C$1297,"C",Checks!$F$2:$F$1297,">=0")),"") -> 0.625 | M24: =COUNTIFS(Checks!$A$2:$A$1297,$C24,Checks!$C$2:$C$1297,"C",Checks!$F$2:$F$1297,">=0") -> 8 | N24: =IFERROR(SUMIFS(Checks!$F$2:$F$1297,Checks!$A$2:$A$1297,$C24,Checks!$C$2:$C$1297,"B")/(2*COUNTIFS(Checks!$A$2:$A$1297,$C24,Checks!$C$2:$C$1297,"B",Checks!$F$2:$F$1297,">=0")),"") -> 0.4 | O24: =COUNTIFS(Checks!$A$2:$A$1297,$C24,Checks!$C$2:$C$1297,"B",Checks!$F$2:$F$1297,">=0") -> 5 | P24: =IFERROR(SUMIFS(Checks!$F$2:$F$1297,Checks!$A$2:$A$1297,$C24,Checks!$C$2:$C$1297,"T")/(2*COUNTIFS(Checks!$A$2:$A$1297,$C24,Checks!$C$2:$C$1297,"T",Checks!$F$2:$F$1297,">=0")),"") -> 0.7 | Q24: =COUNTIFS(Checks!$A$2:$A$1297,$C24,Checks!$C$2:$C$1297,"T",Checks!$F$2:$F$1297,">=0") -> 5 | R24: =IFERROR(SUMIFS(Checks!$F$2:$F$1297,Checks!$A$2:$A$1297,$C24,Checks!$C$2:$C$1297,"N")/(2*COUNTIFS(Checks!$A$2:$A$1297,$C24,Checks!$C$2:$C$1297,"N",Checks!$F$2:$F$1297,">=0")),"") -> 0.5 | S24: =COUNTIFS(Checks!$A$2:$A$1297,$C24,Checks!$C$2:$C$1297,"N",Checks!$F$2:$F$1297,">=0") -> 3 | T24: =K24+M24+O24+Q24+S24 -> 29 | U24: =T24/29 -> 1 | V24: =IF(T24>=26,"High",IF(T24>=20,"Medium","Low")) -> High | W24: =IF((IF(K24>0,Rubric!$C$3,0)+IF(M24>0,Rubric!$C$4,0)+IF(O24>0,Rubric!$C$5,0)+IF(Q24>0,Rubric!$C$6,0)+IF(S24>0,Rubric!$C$7,0))=0,"",ROUND(100*(IF(K24>0,Rubric!$C$3*J24,0)+IF(M24>0,Rubric!$C$4*L24,0)+IF(O24>0,Rubric!$C$5*N24,0)+IF(Q24>0,Rubric!$C$6*P24,0)+IF(S24>0,Rubric!$C$7*R24,0))/(IF(K24>0,Rubric!$C$3,0)+IF(M24>0,Rubric!$C$4,0)+IF(O24>0,Rubric!$C$5,0)+IF(Q24>0,Rubric!$C$6,0)+IF(S24>0,Rubric!$C$7,0)),1)) -> 61 | X24: =IF(W24="","",IF(W24>=Rubric!$C$11,"A",IF(W24>=Rubric!$C$12,"B",IF(W24>=Rubric!$C$13,"C",IF(W24>=Rubric!$C$14,"D","F"))))) -> C | Y24: =IF(X24="","",IF(X24="A","Benchmark",IF(X24="B","Strong",IF(X24="C","Developing",IF(X24="D","Needs work","At risk"))))) -> Developing | Z24: =IF(COUNT(J24,L24,N24,P24,R24)=0,"",INDEX({"Findability","Catalog","Buy","Trust","Content"},MATCH(MIN(J24,L24,N24,P24,R24),CHOOSE({1,2,3,4,5},J24,L24,N24,P24,R24),0))) -> Buy | AA24: https://mousabatarseh.com/federal-fluid-power-review/ | AB24: All pages fetched with curl (no 403/429). PDPs are server-rendered except the Hyva gallery/alt binding. Sitemap totals: only files 001, 005 and 009 of 9 were downloaded (54,496 URLs); the other six were not fetched to stay within the fetch cap, so site-wide figures are extrapolations from those three. Indeed job page could not be retrieved (WebFetch of the jk URL returned a different expired posting; Indeed MCP rate-limited), so posting text comes from the target brief. patriothyd.com is the same Magento install (same static version 1789741354, identical robots.txt listing both sitemaps) with the same SKUs, prices and copy; 2/2 sampled SKUs exist on both domains with self-referencing canonicals.
A25: =IF(W25="","",RANK(W25,$W$2:$W$25,0)) -> 13 | B25: =IF(W25="","",1+COUNTIFS($D$2:$D$25,"Benchmark",$W$2:$W$25,">"&W25)) -> 12 | C25: Royal Apparel, Inc. | D25: Target | E25: Manufacturer (USA-made blank apparel; wholesale B2B + retail + promo channels) | F25: Custom (WAM / liveb2b CGI templates) | G25: Hauppauge, NY | H25: https://www.royalapparel.net | I25: 2026-09-28 | J25: =IFERROR(SUMIFS(Checks!$F$2:$F$1297,Checks!$A$2:$A$1297,$C25,Checks!$C$2:$C$1297,"F")/(2*COUNTIFS(Checks!$A$2:$A$1297,$C25,Checks!$C$2:$C$1297,"F",Checks!$F$2:$F$1297,">=0")),"") -> 0.6875 | K25: =COUNTIFS(Checks!$A$2:$A$1297,$C25,Checks!$C$2:$C$1297,"F",Checks!$F$2:$F$1297,">=0") -> 8 | L25: =IFERROR(SUMIFS(Checks!$F$2:$F$1297,Checks!$A$2:$A$1297,$C25,Checks!$C$2:$C$1297,"C")/(2*COUNTIFS(Checks!$A$2:$A$1297,$C25,Checks!$C$2:$C$1297,"C",Checks!$F$2:$F$1297,">=0")),"") -> 0.875 | M25: =COUNTIFS(Checks!$A$2:$A$1297,$C25,Checks!$C$2:$C$1297,"C",Checks!$F$2:$F$1297,">=0") -> 8 | N25: =IFERROR(SUMIFS(Checks!$F$2:$F$1297,Checks!$A$2:$A$1297,$C25,Checks!$C$2:$C$1297,"B")/(2*COUNTIFS(Checks!$A$2:$A$1297,$C25,Checks!$C$2:$C$1297,"B",Checks!$F$2:$F$1297,">=0")),"") -> 0.7 | O25: =COUNTIFS(Checks!$A$2:$A$1297,$C25,Checks!$C$2:$C$1297,"B",Checks!$F$2:$F$1297,">=0") -> 5 | P25: =IFERROR(SUMIFS(Checks!$F$2:$F$1297,Checks!$A$2:$A$1297,$C25,Checks!$C$2:$C$1297,"T")/(2*COUNTIFS(Checks!$A$2:$A$1297,$C25,Checks!$C$2:$C$1297,"T",Checks!$F$2:$F$1297,">=0")),"") -> 0.9 | Q25: =COUNTIFS(Checks!$A$2:$A$1297,$C25,Checks!$C$2:$C$1297,"T",Checks!$F$2:$F$1297,">=0") -> 5 | R25: =IFERROR(SUMIFS(Checks!$F$2:$F$1297,Checks!$A$2:$A$1297,$C25,Checks!$C$2:$C$1297,"N")/(2*COUNTIFS(Checks!$A$2:$A$1297,$C25,Checks!$C$2:$C$1297,"N",Checks!$F$2:$F$1297,">=0")),"") -> 0.66666667 | S25: =COUNTIFS(Checks!$A$2:$A$1297,$C25,Checks!$C$2:$C$1297,"N",Checks!$F$2:$F$1297,">=0") -> 3 | T25: =K25+M25+O25+Q25+S25 -> 29 | U25: =T25/29 -> 1 | V25: =IF(T25>=26,"High",IF(T25>=20,"Medium","Low")) -> High | W25: =IF((IF(K25>0,Rubric!$C$3,0)+IF(M25>0,Rubric!$C$4,0)+IF(O25>0,Rubric!$C$5,0)+IF(Q25>0,Rubric!$C$6,0)+IF(S25>0,Rubric!$C$7,0))=0,"",ROUND(100*(IF(K25>0,Rubric!$C$3*J25,0)+IF(M25>0,Rubric!$C$4*L25,0)+IF(O25>0,Rubric!$C$5*N25,0)+IF(Q25>0,Rubric!$C$6*P25,0)+IF(S25>0,Rubric!$C$7*R25,0))/(IF(K25>0,Rubric!$C$3,0)+IF(M25>0,Rubric!$C$4,0)+IF(O25>0,Rubric!$C$5,0)+IF(Q25>0,Rubric!$C$6,0)+IF(S25>0,Rubric!$C$7,0)),1)) -> 77.6 | X25: =IF(W25="","",IF(W25>=Rubric!$C$11,"A",IF(W25>=Rubric!$C$12,"B",IF(W25>=Rubric!$C$13,"C",IF(W25>=Rubric!$C$14,"D","F"))))) -> B | Y25: =IF(X25="","",IF(X25="A","Benchmark",IF(X25="B","Strong",IF(X25="C","Developing",IF(X25="D","Needs work","At risk"))))) -> Strong | Z25: =IF(COUNT(J25,L25,N25,P25,R25)=0,"",INDEX({"Findability","Catalog","Buy","Trust","Content"},MATCH(MIN(J25,L25,N25,P25,R25),CHOOSE({1,2,3,4,5},J25,L25,N25,P25,R25),0))) -> Content | AA25: https://mousabatarseh.com/royal-apparel-review/ | AB25: Homepage / is a 515-byte static stub (meta refresh 0 + JS location.replace) to marketing.p, which 301s to /index; the stub has a self-canonical but no title/description, /index has title+description but no canonical. Category grids and PDP buy boxes are rendered client-side from inline JSON (prodJSON, $.wam.browse.init) so prices, colors, sizes and add-to-cart are absent from server HTML; pagination is hash-based (#page=2). Stock levels and add-to-cart could not be observed (no cart/login actions taken). /product/15250006/USA-Team-Beanie.html returns 200 with 'Product Not Found' (soft 404). LinkedIn job page blocked by robots for WebFetch; posting text taken from a mirror (thesocialmediaassociation.com). Fetch tally: ~39 GETs + 17 HEADs on the target, all logged in captures/index.txt.
C27: Benchmark average | W27: =ROUND(AVERAGEIF(D2:D25,"Benchmark",W2:W25),1) -> 75.9
C28: Benchmark median
C29: Rank on the benchmark = where a target would place among the 21 Michigan stores if it joined the index (1 = best). Targets are shaded blue and are not part of the public ShelfMark index.

Sheet Rubric
A1: Pillars & weights
A2: Pillar | B2: Name | C2: Weight | D2: Question the pillar answers
A3: F | B3: Findability | C3: 25 | D3: Can search engines and shoppers find the store and its products?
A4: C | B4: Catalog | C4: 30 | D4: Is the product data complete enough to sell from?
A5: B | B5: Buy | C5: 20 | D5: Is there a clear, trustworthy path from product to purchase?
A6: T | B6: Trust | C6: 15 | D6: Does the site prove there is a real, reachable business behind it?
A7: N | B7: Content | C7: 10 | D7: Does the store publish anything that helps a shopper decide?
B8: Total | C8: =SUM(C3:C7) -> 100
A10: Grade thresholds (score ≥)
A11: A | B11: Benchmark | C11: 85
A12: B | B12: Strong | C12: 70
A13: C | B13: Developing | C13: 55
A14: D | B14: Needs work | C14: 40
A15: F | B15: At risk | C15: below D
A16: Confidence: High = 26+ verified checks, Medium = 20–25, Low = under 20 (of 29).
A17: Deloitte Digital for Google, “Milliseconds Make Millions” (2020): a 0.1 s mobile speed improvement was associated with +8.4% retail conversion and +9.2% AOV (correlational). Core Web Vitals thresholds (web.dev): LCP ≤ 2.5 s, INP ≤ 200 ms, CLS ≤ 0.1. Used only as context — the rubric does not score speed.
A19: The 29 checks
A20: ID | B20: Check | C20: Pillar | D20: Scores 2 when… | E20: Scores 1 when… | F20: Scores 0 when… | H20: Published reference (where one exists)
A21: F1 | B21: HTTPS | C21: F | D21: Site serves on https (final URL https) | E21: Mixed / uncertain | F21: http only
A22: F2 | B22: robots.txt | C22: F | D22: Present, does not block products/categories, contains a Sitemap: line | E22: Present but no Sitemap line, or blocks something important | F22: Missing, or Disallow: / for everything | H22: Google Search Central — robots.txt introduction and the Sitemap directive · https://developers.google.com/search/docs/crawling-indexing/robots/intro
A23: F3 | B23: XML sitemap | C23: F | D23: Reachable and includes product/category (or article) URLs | E23: Reachable but thin / only static pages | F23: Not reachable | H23: Google Search Central — Build and submit a sitemap (50,000 URLs / 50 MB per file) · https://developers.google.com/search/docs/crawling-indexing/sitemaps/build-sitemap
A24: F4 | B24: Title tags | C24: F | D24: Homepage title is descriptive (brand + what/where) AND a sampled product title is unique and descriptive | E24: Present but generic / duplicated / templated | F24: Missing or just 'Home' | H24: Google Search Central — Influencing your title links in search results · https://developers.google.com/search/docs/appearance/title-link
A25: F5 | B25: Meta descriptions | C25: F | D25: Specific meta description on homepage AND on a sampled product page | E25: On one only, or templated / duplicated | F25: None | H25: Google Search Central — Control your snippets in search results (unique descriptions per page) · https://developers.google.com/search/docs/appearance/snippet
A26: F6 | B26: Canonical tags | C26: F | D26: Canonical present on homepage AND product page | E26: On one only | F26: None | H26: Google Search Central — Consolidate duplicate URLs with canonicals · https://developers.google.com/search/docs/crawling-indexing/consolidate-duplicate-urls
A27: F7 | B27: Structured data | C27: F | D27: Product/Breadcrumb schema evidence seen on product pages | E27: Partial evidence (e.g. breadcrumb schema only) | F27: None seen where expected | H27: Google Search Central — Product structured data (Offer, availability, aggregateRating rules) · https://developers.google.com/search/docs/appearance/structured-data/product
A28: F8 | B28: Clean URLs | C28: F | D28: Readable hyphenated product/category URLs, no session IDs | E28: Readable but awkward separators or numeric IDs appended | F28: Query-string-only product URLs | H28: Google Search Central — URL structure best practices · https://developers.google.com/search/docs/crawling-indexing/url-structure
A29: C1 | B29: Product titles | C29: C | D29: Descriptive and consistent (brand / type / size or count) | E29: Partially descriptive | F29: Vague / inconsistent
A30: C2 | B30: Descriptions | C30: C | D30: >=50 words of specific copy on both sampled products | E30: Short / boilerplate (<50 words) or only one product | F30: Missing
A31: C3 | B31: Imagery | C31: C | D31: >=2 images per product (gallery) with alt text | E31: One image, or missing alt text | F31: None / placeholder
A32: C4 | B32: Price & availability | C32: C | D32: Price AND stock state visible (B2B: clear 'login for pricing' plus how to get an account) | E32: Price only, no availability | F32: Neither / unclear
A33: C5 | B33: Variants & specs | C33: C | D33: Structured variant selectors and/or a spec table | E33: Variants only described in text | F33: None where expected
A34: C6 | B34: Taxonomy & breadcrumbs | C34: C | D34: Logical category tree (>=2 levels) AND breadcrumbs | E34: Categories but no breadcrumbs | F34: Flat / none
A35: C7 | B35: Filters & sort | C35: C | D35: Filters (price / type / attribute) AND sort on category pages | E35: Sort or pagination only | F35: None
A36: C8 | B36: Site search | C36: C | D36: Search box with a results page | E36: Search present but weak / unclear | F36: None
A37: B1 | B37: Primary CTA | C37: B | D37: Add to cart / order / request a quote prominent on product page AND homepage | E37: Present but buried | F37: No path to buy or enquire
A38: B2 | B38: Shipping & returns | C38: B | D38: Shipping AND returns info with specifics (thresholds, timelines) linked from product page or footer | E38: Generic policy page only | F38: None | H38: FTC Mail, Internet, or Telephone Order Merchandise Rule (shipping-time representations) · https://www.ftc.gov/legal-library/browse/rules/mail-internet-or-telephone-order-merchandise-rule
A39: B3 | B39: Checkout access | C39: B | D39: Guest checkout, or for B2B a clear become-a-customer application with steps | E39: Account required but sign-up exists | F39: No way to buy online
A40: B4 | B40: Merchandising | C40: B | D40: Homepage features collections / seasonal / new / best sellers with working links | E40: Static links only | F40: None
A41: B5 | B41: Trust signals | C41: B | D41: Product or store reviews PLUS guarantees / awards / secure badges | E41: One type only | F41: None
A42: T1 | B42: Contact | C42: T | D42: Phone + physical address + form or email | E42: Form or email only | F42: None
...

Sheet Checks
A1: Store | B1: Source | C1: Pillar | D1: Check ID | E1: Check | F1: Score | G1: Evidence (what was observed, 2026-09-28)
A2: Stormy Kromer | B2: Benchmark | C2: F | D2: F1 | E2: HTTPS | F2: 2 | G2: Canonical https://www.stormykromer.com/; all pages fetched over https
A3: Stormy Kromer | B3: Benchmark | C3: F | D3: F2 | E3: robots.txt | F3: 2 | G3: Disallows only account/cart/checkout/search.php/admin; 'Sitemap: https://www.stormykromer.com/xmlsitemap.php' (GPTBot fully blocked)
A4: Stormy Kromer | B4: Benchmark | C4: F | D4: F3 | E4: XML sitemap | F4: 2 | G4: /sitemap.xml 404 but /xmlsitemap.php is an index with type=products, type=categories, type=pages, type=brands child sitemaps
A5: Stormy Kromer | B5: Benchmark | C5: F | D5: F4 | E5: Title tags | F5: 2 | G5: Home 'Rugged Wool Caps & Accessories Since 1903 | Stormy Kromer®'; PDP 'The Rancher Insulated Wool Cap | Stormy Kromer®'
